#VRML_SIM R2021a utf8
WorldInfo {
  basicTimeStep 16
  coordinateSystem "NUE"
}
Viewpoint {
  orientation -0.06170063062751387 -0.9961459317839527 -0.062340314167059645 1.5849715285010215
  position -1.0648339993284015 0.30762307643107517 -0.0005514903467397518
  follow "FormulaPi"
}
TexturedBackground {
  reflections FALSE
}
TexturedBackgroundLight {
  castShadows FALSE
}
Floor {
  size 1 1
  appearance Parquetry {
    type "light strip"
  }
}
Solid {
  translation 0 0 -0.5
  children [
    DEF MYWALL_SHAPE Shape {
      appearance Appearance {
        material Material {
          ambientIntensity 1
          diffuseColor 1 1 1
          shininess 0
        }
        texture ImageTexture {
          url [
            ""
          ]
          filtering 0
        }
      }
      geometry Box {
        size 1 0.1 0.01
      }
    }
  ]
  name "solid(2)"
  boundingObject USE MYWALL_SHAPE
}
Solid {
  translation 0 0 0.5
  children [
    USE MYWALL_SHAPE
  ]
  name "solid(3)"
  boundingObject USE MYWALL_SHAPE
}
Solid {
  translation 0.5 0 0
  rotation 0 1 0 -1.5707953071795862
  children [
    USE MYWALL_SHAPE
  ]
  name "solid(4)"
  boundingObject USE MYWALL_SHAPE
}
Solid {
  translation -0.5 0 0
  rotation 0 1 0 -1.5707953071795862
  children [
    USE MYWALL_SHAPE
  ]
  name "solid(5)"
  boundingObject USE MYWALL_SHAPE
}
Solid {
  translation 0.47 0.2 -0.01
  rotation 0 1 0 1.5708
  children [
    DEF APRILTAG Shape {
      appearance Appearance {
        material Material {
          ambientIntensity 1
          diffuseColor 0 0 0
          shininess 0
        }
        texture ImageTexture {
          url [
            "/Users/sina/code/webotstest_project/Tags/200.jpg"
          ]
          filtering 0
        }
      }
      geometry Box {
        size 0.2 0.2 0.001
      }
      castShadows FALSE
      isPickable FALSE
    }
  ]
  name "solid(6)"
}
Robot {
  translation 0 0.03 0
  children [
    HingeJoint {
      jointParameters HingeJointParameters {
        axis 0 0 1
        anchor -0.05 -0.01 -0.04
      }
      device [
        PositionSensor {
          name "encoder1"
          resolution 100
        }
        RotationalMotor {
          name "wheel1"
        }
      ]
      endPoint DEF FPI_WHEEL_SOLID Solid {
        translation -0.050000010446274314 -0.009999983508627415 -0.040000204893057216
        rotation -0.9999997413845406 -0.0004891891381648099 -0.0005271857728183414 4.712357518886945
        children [
          DEF FPI_WHEEL_SHAPE Shape {
            appearance PBRAppearance {
              baseColor 1 1 0
              roughness 1
              metalness 0
              IBLStrength 2
            }
            geometry Cylinder {
              height 0.011
              radius 0.015
            }
            castShadows FALSE
          }
        ]
        name "wheel1solid"
        boundingObject USE FPI_WHEEL_SHAPE
        physics DEF FPI_WHEEL_PHYSICS Physics {
          mass 0.01
        }
      }
    }
    HingeJoint {
      jointParameters HingeJointParameters {
        axis 0 0 1
        anchor -0.05 -0.01 0.04
      }
      device [
        PositionSensor {
          name "encoder2"
        }
        RotationalMotor {
          name "wheel2"
        }
      ]
      endPoint Solid {
        translation -0.05000040511046916 -0.009999966447101535 0.04000017737174681
        rotation -0.9999997413859814 -0.0004891853527303809 -0.0005271865522787222 4.712357512699858
        children [
          USE FPI_WHEEL_SHAPE
        ]
        name "wheel2solid"
        boundingObject USE FPI_WHEEL_SHAPE
        physics USE FPI_WHEEL_PHYSICS
      }
    }
    Hinge2Joint {
      jointParameters HingeJointParameters {
        axis 0 1 0
        anchor 0.05 -0.01 0.04
        suspensionAxis 0 1 0
      }
      jointParameters2 JointParameters {
      }
      device [
        RotationalMotor {
          name "servo3"
          minPosition -1.47
          maxPosition 1.47
        }
      ]
      endPoint Solid {
        translation 0.049999179093319766 -0.010000137237356661 0.039999873748849155
        rotation -0.9988772709645318 -0.033747381025373904 -0.03324623022806795 4.711307809365804
        children [
          USE FPI_WHEEL_SHAPE
        ]
        name "wheel3solid"
        boundingObject USE FPI_WHEEL_SHAPE
        physics USE FPI_WHEEL_PHYSICS
      }
    }
    Hinge2Joint {
      jointParameters HingeJointParameters {
        axis 0 1 0
        anchor 0.05 -0.01 -0.04
      }
      jointParameters2 JointParameters {
      }
      device [
        RotationalMotor {
          name "servo4"
          minPosition -1.57
          maxPosition 1.57
        }
      ]
      endPoint Solid {
        translation 0.04999967284569962 -0.010000011958636805 -0.03999976577618417
        rotation -0.9990173756849533 -0.03160515187985823 -0.031070845727144365 4.711474002381789
        children [
          USE FPI_WHEEL_SHAPE
        ]
        name "wheel4solid"
        boundingObject USE FPI_WHEEL_SHAPE
        physics USE FPI_WHEEL_PHYSICS
      }
    }
    DEF FPI_BODY_SHAPE Shape {
      appearance PBRAppearance {
        baseColor 0.1 1 0.1
        metalness 0.1
        IBLStrength 2
      }
      geometry Box {
        size 0.12 0.025 0.05
      }
      castShadows FALSE
    }
    Camera {
      translation -0.05 0.04 0
      rotation 0.1294279597735375 -0.9831056944488314 0.1294279597735375 1.58783
      children [
        Shape {
          appearance DEF cam_appearance PBRAppearance {
            baseColor 0.5 0.5 0.5
          }
          geometry Box {
            size 0.02 0.02 0.02
          }
        }
      ]
      name "fpi_cam"
      width 640
      height 480
      antiAliasing TRUE
    }
    Solid {
      translation -0.05 0.02 0
      children [
        Shape {
          appearance USE cam_appearance
          geometry Cylinder {
            height 0.03
            radius 0.005
          }
        }
      ]
      name "cam_stand_solid"
    }
  ]
  name "FormulaPi"
  boundingObject USE FPI_BODY_SHAPE
  physics Physics {
  }
  controller "<extern>"
}
